Workbook

Sheet T3
A1: RFP EVALUATION STAGE I : PROJECT ACTIVE DIRECTORY AND EMAIL STRUCTURE
A3: Tenderer No : | B3: 1 | C3: Getronics Solutions (Malaysia) Sdn Bhd
A5: Date :
A7: Evaluator :
C9: SCORING
C10: 0-Lowest -------------------------------> 5-Highest
A12: No. | B12: RFP Section | D12: Score | E12: Comments
C13: COMPANY PROFILE (30%)
A14: 1 | B14: 5.1.1 | C14: Executive Summary (5 Marks)
C15: Executive Summary
B16: 5.1.2 | C16: Statement of Capability (30 Marks)
A17: 1 | B17: 5.1.2.1 | C17: Company Profile
A18: 2 | B18: 5.1.2.2 | C18: Qualifications
A19: 3 | B19: 5.1.2.3 | C19: Resources / capabilities
A20: 4 | B20: 5.1.2.4 | C20: Subcontractors
A21: 5 | B21: 5.1.2.5 | C21: Relevant clients
A22: 6 | B22: 5.1.2.6 | C22: Local Support Team
C23: IMPLEMENTATION STRATEGY (40%)
B24: 5.1.3 | C24: Scope of work (15 Marks)
A25: 1 | B25: 5.1.3.1 | C25: Methodology
A26: 2 | B26: 5.1.3.2 | C26: Implementation Approach
A27: 3 | B27: 5.1.3.3 | C27: Project Team Structure
B28: 5.1.5 | C28: Project Management (10 Marks)
A29: 1 | B29: 5.1.5.1 | C29: Management & Reporting
A30: 2 | B30: 5.1.5.2 | C30: Quality Assurance
B31: 5.1.8 | C31: Implementation Plan (20 Marks)
A32: 1 | B32: 5.1.8.1 | C32: Proposed Timeline
A33: 2 | B33: 5.1.8.2 | C33: Proposed Phases
A34: 3 | B34: 5.1.8.3 | C34: Proposed Milestones & Deliverables
A35: 4 | B35: 5.1.8.4 | C35: Dependencies
C36: SUPPORT (15%)
B37: 5.1.6 | C37: Vendor Support (35 Marks)
A38: 1 | B38: 5.1.6.1 | C38: Software License, Implementation and Maintenance Agreement
A39: 2 | B39: 5.1.6.2 | C39: Warranty Period
A40: 3 | B40: 5.1.6.3 | C40: Online Assistance
A41: 4 | B41: 5.1.6.4 | C41: Response Time
A42: 5 | B42: 5.1.6.5 | C42: Remote Support
A43: 6 | B43: 5.1.6.6 | C43: Administrator/User Training
A44: 7 | B44: 5.1.6.7 | C44: User Focus Group
B45: 5.1.7 | C45: Resources (20 Marks)
...

Sheet T6
A1: RFP EVALUATION STAGE I : PROJECT ACTIVE DIRECTORY AND EMAIL STRUCTURE
A3: Tenderer No : | B3: 1 | C3: Millennium Radius Sdn Bhd
A5: Date :
A7: Evaluator :
C9: SCORING
C10: 0-Lowest -------------------------------> 5-Highest
A12: No. | B12: RFP Section | D12: Score | E12: Comments
C13: COMPANY PROFILE (30%)
A14: 1 | B14: 5.1.1 | C14: Executive Summary (5 Marks)
C15: Executive Summary
B16: 5.1.2 | C16: Statement of Capability
A17: 1 | B17: 5.1.2.1 | C17: Company Profile
A18: 2 | B18: 5.1.2.2 | C18: Qualifications
A19: 3 | B19: 5.1.2.3 | C19: Resources / capabilities
A20: 4 | B20: 5.1.2.4 | C20: Subcontractors
A21: 5 | B21: 5.1.2.5 | C21: Relevant clients
A22: 6 | B22: 5.1.2.6 | C22: Local Support Team
C23: IMPLEMENTATION STRATEGY (40%)
B24: 5.1.3 | C24: Scope of work
A25: 1 | B25: 5.1.3.1 | C25: Methodology
A26: 2 | B26: 5.1.3.2 | C26: Implementation Approach
A27: 3 | B27: 5.1.3.3 | C27: Project Team Structure
B28: 5.1.5 | C28: Project Management
A29: 1 | B29: 5.1.5.1 | C29: Management & Reporting
A30: 2 | B30: 5.1.5.2 | C30: Quality Assurance
B31: 5.1.8 | C31: Implementation Plan
A32: 1 | B32: 5.1.8.1 | C32: Proposed Timeline
A33: 2 | B33: 5.1.8.2 | C33: Proposed Phases
A34: 3 | B34: 5.1.8.3 | C34: Proposed Milestones & Deliverables
A35: 4 | B35: 5.1.8.4 | C35: Dependencies
C36: SUPPORT (15%)
B37: 5.1.6 | C37: Vendor Support
A38: 1 | B38: 5.1.6.1 | C38: Software License, Implementation and Maintenance Agreement
A39: 2 | B39: 5.1.6.2 | C39: Warranty Period
A40: 3 | B40: 5.1.6.3 | C40: Online Assistance
A41: 4 | B41: 5.1.6.4 | C41: Response Time
A42: 5 | B42: 5.1.6.5 | C42: Remote Support
A43: 6 | B43: 5.1.6.6 | C43: Administrator/User Training
A44: 7 | B44: 5.1.6.7 | C44: User Focus Group
B45: 5.1.7 | C45: Resources
...

Sheet Bright Nexus
A1: RFP EVALUATION STAGE I : To Implement Content Filter and Redundant Tier 2 Firewall for SME Bank
A3: Tenderer : | C3: Bright Nexus Sdn Bhd
A5: Date :
A7: Evaluator :
C9: SCORING
C10: 0-Lowest -------------------------------> 5-Highest
A12: No. | B12: RFP Section | D12: Score | E12: Comments
C13: COMPANY PROFILE (30%)
A14: 1 | B14: 5.1.1 | C14: Executive Summary (5 Marks)
C15: Executive Summary | D15: 0
C16: Marks | D16: 0
B17: 5.1.2 | C17: Statement of Capability (30 Marks)
A18: 1 | B18: 5.1.2.1 | C18: Company Profile | D18: 0
A19: 2 | B19: 5.1.2.2 | C19: Qualifications | D19: 0
A20: 3 | B20: 5.1.2.3 | C20: Resources / capabilities | D20: 0
A21: 4 | B21: 5.1.2.4 | C21: Subcontractors | D21: 0
A22: 5 | B22: 5.1.2.5 | C22: Relevant clients | D22: 0
A23: 6 | B23: 5.1.2.6 | C23: Local Support Team | D23: 0
C24: Marks | D24: =SUM(D18:D23) -> 0
C25: Total Marks / 35 | D25: =SUM(D24,D16) -> 0
C26: Percentage (%) | D26: =(D25) /35 * 30 -> 0
C27: IMPLEMENTATION STRATEGY (40%)
B28: 5.1.3 | C28: Scope of work (15 Marks)
A29: 1 | B29: 5.1.3.1 | C29: Methodology | D29: 0
A30: 2 | B30: 5.1.3.2 | C30: Implementation Approach | D30: 0
A31: 3 | B31: 5.1.3.3 | C31: Project Team Structure | D31: 0
C32: Marks | D32: =SUM(D29:D31) -> 0
B33: 5.1.5 | C33: Project Management (10 Marks)
A34: 1 | B34: 5.1.5.1 | C34: Management & Reporting | D34: 0
A35: 2 | B35: 5.1.5.2 | C35: Quality Assurance | D35: 0
C36: Marks | D36: =SUM(D34:D35) -> 0
B37: 5.1.8 | C37: Implementation Plan (20 Marks)
A38: 1 | B38: 5.1.8.1 | C38: Proposed Timeline | D38: 0
A39: 2 | B39: 5.1.8.2 | C39: Proposed Phases | D39: 0
A40: 3 | B40: 5.1.8.3 | C40: Proposed Milestones & Deliverables | D40: 0
A41: 4 | B41: 5.1.8.4 | C41: Dependencies | D41: 0
C42: Marks | D42: =SUM(D38:D41) -> 0
C43: Total Marks / 45 | D43: =SUM(D32,D36,D42) -> 0
C44: Percentage (%) | D44: =(D43) /45 * 40 -> 0
C45: SUPPORT (15%)
...

Sheet Summary
A1: version 1.1 - May2021
B2: Individual Tech Evaluation Scoring
B3: Please provide information below (will be reflected to each Tenderer's Sheets)
B5: RFP Title : | C5: CBS INFRASTRUCTURE MAINTENANCE AND WARRANTY SUPPORT
B6: Evaluator : | C6: Mohd Faiz Ibrahim Sawal
B7: Eval.Date : | C7: 45860
B8: RFP Issuance :
B9: RFP Closing :
B11: Summary Scoring Table
B12: Scoring below will be auto-populate from each Tenderer's sheet
B13: Change the Tenderers Company Name, add rows and sheets if necessary
D14: Evaluator
B15: TENDERER NO | C15: TENDERER'S COMPANY | D15: =C6 -> Mohd Faiz Ibrahim Sawal | F15: TOTAL SCORE (100%) | G15: TECHNICAL SCORE (90%) | H15: Rank
B16: 1 | C16: 3F RESOURCES SDN BHD | D16: ='3F Resources'!D67 -> 86.21 | F16: =D16 -> 86.21 | G16: =ROUND((F16*0.9),2) -> 77.59 | H16: =RANK(G16,$G$16:$G$19) -> 2
B17: 2 | C17: FRONIX SDN BHD | D17: =Fronix!D67 -> 97.74 | F17: =D17 -> 97.74 | G17: =ROUND((F17*0.9),2) -> 87.97 | H17: =RANK(G17,$G$16:$G$19) -> 1
B18: 3 | C18: QUBE APPS SOLUTION SDN BHD | D18: ='Qube Apps'!D67 -> 12.72 | F18: =D18 -> 12.72 | G18: =ROUND((F18*0.9),2) -> 11.45 | H18: =RANK(G18,$G$16:$G$19) -> 4
B19: 4 | C19: RAFATECH SYSTEM SDN BHD | D19: =Rafatech!D67 -> 79.07 | F19: =D19 -> 79.07 | G19: =ROUND((F19*0.9),2) -> 71.16 | H19: =RANK(G19,$G$16:$G$19) -> 3
D22: Sections
B23: TENDERER NO | C23: TENDERER'S COMPANY | D23: A - Company Profile (15%) | E23: B - Implementation Strategy (10%) | F23: C - Support (10%) | G23: D - Compliance (60%) | H23: E - Team (5%) | I23: TOTAL SCORE (100%) | J23: TECHNICAL SCORE (90%) | L23: Value Added (5 Marks) | M23: Remarks
B24: 1 | C24: =C16 -> 3F RESOURCES SDN BHD | D24: ='3F Resources'!D25 -> 11.14 | E24: ='3F Resources'!D37 -> 6.57 | F24: ='3F Resources'!D46 -> 8.5 | G24: ='3F Resources'!D57 -> 56 | H24: ='3F Resources'!D65 -> 4 | I24: =SUM(D24:H24) -> 86.21 | J24: =I24*0.9 -> 77.589 | L24: ='3F Resources'!D72 -> 0
B25: 2 | C25: =C17 -> FRONIX SDN BHD | D25: =Fronix!D25 -> 14.14 | E25: =Fronix!D37 -> 9.43 | F25: =Fronix!D46 -> 9.5 | G25: =Fronix!D57 -> 60 | H25: =Fronix!D65 -> 4.67 | I25: =SUM(D25:H25) -> 97.74 | J25: =I25*0.9 -> 87.966 | L25: =Fronix!D72 -> 3
B26: 3 | C26: =C18 -> QUBE APPS SOLUTION SDN BHD | D26: ='Qube Apps'!D25 -> 0.86 | E26: ='Qube Apps'!D37 -> 0.86 | F26: ='Qube Apps'!D46 -> 0 | G26: ='Qube Apps'!D57 -> 10 | H26: ='Qube Apps'!D65 -> 1 | I26: =SUM(D26:H26) -> 12.72 | J26: =I26*0.9 -> 11.448 | L26: ='Qube Apps'!D72 -> 0
B27: 4 | C27: =C19 -> RAFATECH SYSTEM SDN BHD | D27: =Rafatech!D25 -> 9.86 | E27: =Rafatech!D37 -> 5.71 | F27: =Rafatech!D46 -> 7.5 | G27: =Rafatech!D57 -> 52 | H27: =Rafatech!D65 -> 4 | I27: =SUM(D27:H27) -> 79.07 | J27: =I27*0.9 -> 71.163 | L27: =Rafatech!D72 -> 2

Sheet 3F Resources
C1: RFP EVALUATION
C2: CBS INFRASTRUCTURE MAINTENANCE AND WARRANTY SUPPORT
A4: Tenderer | C4: =Summary!C16 -> 3F RESOURCES SDN BHD
A5: Date | C5: =Summary!C7 -> 45860
A6: Evaluator | C6: =Summary!C6 -> Mohd Faiz Ibrahim Sawal
C9: SCORING
C10: 0-Lowest -------------------------------> 5-Highest
A12: No. | B12: RFP Section | D12: Score | E12: Comments
A13: A | C13: COMPANY PROFILE (15%)
B14: 1 | C14: Executive Summary (5 Marks)
B15: 1.1 | C15: Executive Summary | D15: 5
C16: Marks | D16: =SUM(D15) -> 5
B17: 2 | C17: Statement of Capability (30 Marks)
B18: 1.1 | C18: Company Profile | D18: 5
B19: 1.2 | C19: Qualifications | D19: 3
B20: 1.3 | C20: Resources / capabilities | D20: 3
B21: 1.4 | C21: Subcontractors | D21: 3
B22: 1.5 | C22: Relevant clients | D22: 3
B23: 1.6 | C23: Complete Submission | D23: 4
C24: Marks | D24: =D16+SUM(D18:D23) -> 26
C25: Percentage (%) | D25: =ROUND((D24/35*15),2) -> 11.14
A27: B | C27: IMPLEMENTATION STRATEGY (10%)
B28: 2 | C28: Scope of work (35 Marks)
B29: 2.1 | C29: Methodology | D29: 4
B30: 2.2 | C30: Implementation Approach | D30: 3
B31: 2.3 | C31: Project Team Structure | D31: 3
B32: 2.4 | C32: Quality Assurance | D32: 3
B33: 2.5 | C33: Proposed Timeline | D33: 4
B34: 2.6 | C34: Proposed Phases | D34: 3
B35: 2.7 | C35: Proposed Milestones & Deliverables | D35: 3
C36: Marks | D36: =SUM(D29:D35) -> 23
C37: Percentage (%) | D37: =ROUND((D36/35*10),2) -> 6.57
A39: C | C39: SUPPORT (10%)
B40: 3 | C40: Vendor Support (20 Marks)
B41: 3.1 | C41: Warranty Period | D41: 4
B42: 3.2 | C42: Online Support | D42: 5
B43: 3.3 | C43: Response Time | D43: 4
B44: 3.4 | C44: Support Service Offered | D44: 4
C45: Marks | D45: =SUM(D41:D44) -> 17
C46: Percentage (%) | D46: =ROUND((D45/20*10),2) -> 8.5
...

Sheet Fronix
C1: RFP EVALUATION
C2: CBS INFRASTRUCTURE MAINTENANCE AND WARRANTY SUPPORT
A4: Tenderer | C4: =Summary!C17 -> FRONIX SDN BHD
A5: Date | C5: =Summary!C7 -> 45860
A6: Evaluator | C6: =Summary!C6 -> Mohd Faiz Ibrahim Sawal
C9: SCORING
C10: 0-Lowest -------------------------------> 5-Highest
A12: No. | B12: RFP Section | D12: Score | E12: Comments
A13: A | C13: COMPANY PROFILE (15%)
B14: 1 | C14: Executive Summary (5 Marks)
B15: 1.1 | C15: Executive Summary | D15: 5
C16: Marks | D16: =SUM(D15) -> 5
B17: 2 | C17: Statement of Capability (30 Marks)
B18: 1.1 | C18: Company Profile | D18: 5
B19: 1.2 | C19: Qualifications | D19: 5
B20: 1.3 | C20: Resources / capabilities | D20: 5
B21: 1.4 | C21: Subcontractors | D21: 4
B22: 1.5 | C22: Relevant clients | D22: 5
B23: 1.6 | C23: Complete Submission | D23: 4
C24: Marks | D24: =D16+SUM(D18:D23) -> 33
C25: Percentage (%) | D25: =ROUND((D24/35*15),2) -> 14.14
A27: B | C27: IMPLEMENTATION STRATEGY (10%)
B28: 2 | C28: Scope of work (35 Marks)
B29: 2.1 | C29: Methodology | D29: 5
B30: 2.2 | C30: Implementation Approach | D30: 5
B31: 2.3 | C31: Project Team Structure | D31: 5
B32: 2.4 | C32: Quality Assurance | D32: 5
B33: 2.5 | C33: Proposed Timeline | D33: 4
B34: 2.6 | C34: Proposed Phases | D34: 4
B35: 2.7 | C35: Proposed Milestones & Deliverables | D35: 5
C36: Marks | D36: =SUM(D29:D35) -> 33
C37: Percentage (%) | D37: =ROUND((D36/35*10),2) -> 9.43
A39: C | C39: SUPPORT (10%)
B40: 3 | C40: Vendor Support (20 Marks)
B41: 3.1 | C41: Warranty Period | D41: 5
B42: 3.2 | C42: Online Support | D42: 5
B43: 3.3 | C43: Response Time | D43: 5
B44: 3.4 | C44: Support Service Offered | D44: 4
C45: Marks | D45: =SUM(D41:D44) -> 19
C46: Percentage (%) | D46: =ROUND((D45/20*10),2) -> 9.5
...

Sheet Qube Apps
C1: RFP EVALUATION
C2: CBS INFRASTRUCTURE MAINTENANCE AND WARRANTY SUPPORT
A4: Tenderer | C4: =Summary!C18 -> QUBE APPS SOLUTION SDN BHD
A5: Date | C5: =Summary!C7 -> 45860
A6: Evaluator | C6: =Summary!C6 -> Mohd Faiz Ibrahim Sawal
C9: SCORING
C10: 0-Lowest -------------------------------> 5-Highest
A12: No. | B12: RFP Section | D12: Score | E12: Comments
A13: A | C13: COMPANY PROFILE (15%)
B14: 1 | C14: Executive Summary (5 Marks)
B15: 1.1 | C15: Executive Summary | D15: 2
C16: Marks | D16: =SUM(D15) -> 2
B17: 2 | C17: Statement of Capability (30 Marks)
B18: 1.1 | C18: Company Profile | D18: 0
B19: 1.2 | C19: Qualifications | D19: 0
B20: 1.3 | C20: Resources / capabilities | D20: 0
B21: 1.4 | C21: Subcontractors | D21: 0
B22: 1.5 | C22: Relevant clients | D22: 0
B23: 1.6 | C23: Complete Submission | D23: 0
C24: Marks | D24: =D16+SUM(D18:D23) -> 2
C25: Percentage (%) | D25: =ROUND((D24/35*15),2) -> 0.86
A27: B | C27: IMPLEMENTATION STRATEGY (10%)
B28: 2 | C28: Scope of work (35 Marks)
B29: 2.1 | C29: Methodology | D29: 0
B30: 2.2 | C30: Implementation Approach | D30: 0
B31: 2.3 | C31: Project Team Structure | D31: 1
B32: 2.4 | C32: Quality Assurance | D32: 0
B33: 2.5 | C33: Proposed Timeline | D33: 1
B34: 2.6 | C34: Proposed Phases | D34: 1
B35: 2.7 | C35: Proposed Milestones & Deliverables | D35: 0
C36: Marks | D36: =SUM(D29:D35) -> 3
C37: Percentage (%) | D37: =ROUND((D36/35*10),2) -> 0.86
A39: C | C39: SUPPORT (10%)
B40: 3 | C40: Vendor Support (20 Marks)
B41: 3.1 | C41: Warranty Period | D41: 0
B42: 3.2 | C42: Online Support | D42: 0
B43: 3.3 | C43: Response Time | D43: 0
B44: 3.4 | C44: Support Service Offered | D44: 0
C45: Marks | D45: =SUM(D41:D44) -> 0
C46: Percentage (%) | D46: =ROUND((D45/20*10),2) -> 0
...

Sheet Rafatech
C1: RFP EVALUATION
C2: CBS INFRASTRUCTURE MAINTENANCE AND WARRANTY SUPPORT
A4: Tenderer | C4: =Summary!C19 -> RAFATECH SYSTEM SDN BHD
A5: Date | C5: =Summary!C7 -> 45860
A6: Evaluator | C6: =Summary!C6 -> Mohd Faiz Ibrahim Sawal
C9: SCORING
C10: 0-Lowest -------------------------------> 5-Highest
A12: No. | B12: RFP Section | D12: Score | E12: Comments
A13: A | C13: COMPANY PROFILE (15%)
B14: 1 | C14: Executive Summary (5 Marks)
B15: 1.1 | C15: Executive Summary | D15: 3
C16: Marks | D16: =SUM(D15) -> 3
B17: 2 | C17: Statement of Capability (30 Marks)
B18: 1.1 | C18: Company Profile | D18: 5
B19: 1.2 | C19: Qualifications | D19: 3
B20: 1.3 | C20: Resources / capabilities | D20: 3
B21: 1.4 | C21: Subcontractors | D21: 3
B22: 1.5 | C22: Relevant clients | D22: 3
B23: 1.6 | C23: Complete Submission | D23: 3
C24: Marks | D24: =D16+SUM(D18:D23) -> 23
C25: Percentage (%) | D25: =ROUND((D24/35*15),2) -> 9.86
A27: B | C27: IMPLEMENTATION STRATEGY (10%)
B28: 2 | C28: Scope of work (35 Marks)
B29: 2.1 | C29: Methodology | D29: 4
B30: 2.2 | C30: Implementation Approach | D30: 2
B31: 2.3 | C31: Project Team Structure | D31: 3
B32: 2.4 | C32: Quality Assurance | D32: 3
B33: 2.5 | C33: Proposed Timeline | D33: 3
B34: 2.6 | C34: Proposed Phases | D34: 2
B35: 2.7 | C35: Proposed Milestones & Deliverables | D35: 3
C36: Marks | D36: =SUM(D29:D35) -> 20
C37: Percentage (%) | D37: =ROUND((D36/35*10),2) -> 5.71
A39: C | C39: SUPPORT (10%)
B40: 3 | C40: Vendor Support (20 Marks)
B41: 3.1 | C41: Warranty Period | D41: 4
B42: 3.2 | C42: Online Support | D42: 5
B43: 3.3 | C43: Response Time | D43: 4
B44: 3.4 | C44: Support Service Offered | D44: 2
C45: Marks | D45: =SUM(D41:D44) -> 15
C46: Percentage (%) | D46: =ROUND((D45/20*10),2) -> 7.5
...

Sheet Scoring Guidelines
B1: EVALUATION SHEET – SCORING GUIDELINES
D3: 0- Lowest | I3: 5 - Highest
D4: SCORE
B5: No | C5: Criteria | D5: 0 | E5: 1 | F5: 2 | G5: 3 | H5: 4 | I5: 5
A6: A | B6: 1 | C6: Executive Summary | D6: Not Available / Not Applicable | E6: Not confident at all with the company background and financial strength | F6: Less confident based on company background and financial strength | G6: Acceptable on company's background and financial strength | H6: Confident on the company's strength and it is sendirian berhad company | I6: Confident on the company's strength and it is public listed company
B7: 2 | C7: Company Profile | D7: Not Available / Not Applicable | E7: 0% Bumiputera | F7: 25% Bumiputera | G7: 50% Bumiputera | H7: 75% Bumiputera | I7: 100% Bumiputera
B8: 3 | C8: Qualifications Company’s specialty / expertise and past experience in implementing the same project. | D8: Not Available / Not Applicable | E8: I don’t think they have the experience | F8: They might have the potential although their experience may not be direct | G8: They have some base to work on | H8: One of core business and have some reference sites | I8: Core business and already have number of reference sites
B9: 4 | C9: Resources/Staff Strength | D9: Not Available / Not Applicable | E9: Very weak, 1 or none Experience and Certified Engineer | F9: So-so, have at least 1 Experience | G9: Acceptable, have at least 2 Experience | H9: Good, have at least 2 Experience and Certified Engineer | I9: Very Good, have 3 or more Experience and Certified Engineer
B10: 5 | C10: Subcontractors | E10: Rely on subcontractors | G10: Half subcontractors, half staff | I10: No subscontractors
B11: 6 | C11: Relevant clients | D11: Not Available / Not Applicable | E11: 1 or none reference sites | F11: 2 reference sites | G11: 3 reference sites | H11: 4 reference sites | I11: 5 or more reference sites
C12: Complete submission | D12: 0 | E12: 0.1 | F12: 0.3 | G12: 0.5 | H12: 0.7 | I12: 1
A13: B | B13: 6 | C13: Methodology | D13: Not Available / Not Applicable | E13: Not defined properly | F13: Defined a bit | G13: Defined partially | H13: Clearly defined but there some room of improvement | I13: Clearly defined and cover all area
B14: 7 | C14: Implementation Approach | D14: Not Available / Not Applicable | E14: Does not follow any standard | F14: Minimum use of standard practices | G14: Follows some of the standards (acceptable) | H14: Proper management but partially follow the standard | I14: Follow standard practices e.g. ITIL & Prince2
B15: 8 | C15: Project Team Structure | D15: Not Available / Not Applicable | E15: Do not provide any team structure | F15: Partially team structure provided (certified in related field) | G15: Acceptable Team Structure (certified in related field) | H15: Basic team structure with minimum staf allocated (certified in related field) | I15: Complete Team Structure cover all angle (certified in related field)
B16: 9 | C16: User Data Migration, Wipeout | D16: Not Available / Not Applicable | E16: Not defined properly | F16: Defined a bit | G16: Defined partially | H16: Clearly defined but there some room of improvement | I16: Clearly defined and cover all area
B17: 10 | C17: Quality Assurance | D17: Not Available / Not Applicable | E17: Not defined properly | F17: Defined a bit | G17: Defined partially | H17: Clearly defined but there some room of improvement | I17: Clearly defined and follow certain standard. Execution until completion
B18: 11 | C18: Timeline | D18: Not Available / Not Applicable | E18: 6 months | F18: 5 months | G18: 4 months | H18: 3 months | I18: 2 months
B19: 12 | C19: Phases | D19: Not Available / Not Applicable | E19: Not defined properly | F19: Defined a bit | G19: Defined partially | H19: Clearly defined but there some room of improvement | I19: Clearly defined and no amendent required
B20: 13 | C20: Milestones and deliverables | D20: Not Available / Not Applicable | E20: Not defined properly | F20: Defined a bit | G20: Defined partially | H20: Clearly defined but there some room of improvement | I20: Clearly defined and no amendent required
A21: C | B21: 14 | C21: Warranty period | D21: No support | E21: 1 year onsite support NBD | F21: 2 years online support | G21: 2 years on site support NBD | H21: 3 years online support | I21: 3years on site support NBD
B22: 15 | C22: Online support | D22: Don’t have system for tracking support | E22: Support by phone and no tracking | F22: Support by phone and do tracking using excel and not shared | G22: Support by phone and tracking using excel and share with us | H22: Support by system and has system tracking | I22: Support by system, has system tracking and we can view on website
B23: 16 | C23: Response time | D23: Not Available / Not Applicable | E23: Not defined properly | F23: Defined a bit | G23: Defined partially | H23: Clearly defined but there some room of improvement | I23: Clearly defined and no amendent required
B24: 17 | C24: Support Service Offered | D24: Not Available / Not Applicable | E24: Do not provide or not clearly stated on the training program | F24: Meet some of the requirements | G24: Meet half of the requirements | H24: Almost meet requirements | I24: Meet requirements
A25: D | B25: 18 | C25: Refer to Technical Compliance Document
A26: E | B26: 20 | C26: Committed Resources | D26: Not Available / Not Applicable | E26: 1 or less resources | F26: 2 resources | G26: 3 resources | H26: 4 resources | I26: 5 or more resources
B27: 21 | C27: Local Support | D27: No local support | E27: Local support but dependant on other team | F27: Local support, (normal staff) | G27: Half local support, (engineer and normal staff) | H27: All local support, (all normal staff) | I27: All local support, (engineer and normal staff)
B28: 22 | C28: Curriculum Vitae | D28: Not provided | E28: Half summary provided | F28: All summary provided | G28: Half provided with details | H28: More than half provided with details | I28: All provided with details
B30: No | C30: Criteria | D30: 0 | E30: 1 | F30: 2 | G30: 3 | H30: 4 | I30: 5
A31: Value Added | B31: 23 | C31: Value Added | D31: Not Available / Not Applicable | E31: 1 or less added values | F31: 2 added values | G31: 3 added values | H31: 4 added values | I31: 5 or more added values
